Workbook

Sheet Sales-Profit by Region
A1: Sales & Profit by Region (Completed Orders Only)
A4: Region | B4: Completed Sales (₹) | C4: Completed Profit (₹) | D4: Profit Margin | E4: Completed Orders
A5: South | B5: =SUMIFS(CleanRef!$T$2:$T$913,CleanRef!$G$2:$G$913,"South",CleanRef!$AH$2:$AH$913,"Yes") -> 1641550 | C5: =SUMIFS(CleanRef!$U$2:$U$913,CleanRef!$G$2:$G$913,"South",CleanRef!$AH$2:$AH$913,"Yes") -> 468067.93 | D5: =IF(B5=0,0,C5/B5) -> 0.28513779 | E5: =COUNTIFS(CleanRef!$G$2:$G$913,"South",CleanRef!$AH$2:$AH$913,"Yes") -> 153
A6: West | B6: =SUMIFS(CleanRef!$T$2:$T$913,CleanRef!$G$2:$G$913,"West",CleanRef!$AH$2:$AH$913,"Yes") -> 1502507.2 | C6: =SUMIFS(CleanRef!$U$2:$U$913,CleanRef!$G$2:$G$913,"West",CleanRef!$AH$2:$AH$913,"Yes") -> 433402.26 | D6: =IF(B6=0,0,C6/B6) -> 0.2884527 | E6: =COUNTIFS(CleanRef!$G$2:$G$913,"West",CleanRef!$AH$2:$AH$913,"Yes") -> 153
A7: East | B7: =SUMIFS(CleanRef!$T$2:$T$913,CleanRef!$G$2:$G$913,"East",CleanRef!$AH$2:$AH$913,"Yes") -> 1385008.4 | C7: =SUMIFS(CleanRef!$U$2:$U$913,CleanRef!$G$2:$G$913,"East",CleanRef!$AH$2:$AH$913,"Yes") -> 418198.97 | D7: =IF(B7=0,0,C7/B7) -> 0.3019469 | E7: =COUNTIFS(CleanRef!$G$2:$G$913,"East",CleanRef!$AH$2:$AH$913,"Yes") -> 149
A8: North | B8: =SUMIFS(CleanRef!$T$2:$T$913,CleanRef!$G$2:$G$913,"North",CleanRef!$AH$2:$AH$913,"Yes") -> 1293210.4 | C8: =SUMIFS(CleanRef!$U$2:$U$913,CleanRef!$G$2:$G$913,"North",CleanRef!$AH$2:$AH$913,"Yes") -> 389626.99 | D8: =IF(B8=0,0,C8/B8) -> 0.30128663 | E8: =COUNTIFS(CleanRef!$G$2:$G$913,"North",CleanRef!$AH$2:$AH$913,"Yes") -> 128
A9: Unknown | B9: =SUMIFS(CleanRef!$T$2:$T$913,CleanRef!$G$2:$G$913,"Unknown",CleanRef!$AH$2:$AH$913,"Yes") -> 187898.46 | C9: =SUMIFS(CleanRef!$U$2:$U$913,CleanRef!$G$2:$G$913,"Unknown",CleanRef!$AH$2:$AH$913,"Yes") -> 63943.192 | D9: =IF(B9=0,0,C9/B9) -> 0.34030716 | E9: =COUNTIFS(CleanRef!$G$2:$G$913,"Unknown",CleanRef!$AH$2:$AH$913,"Yes") -> 19
A10: TOTAL | B10: =SUM(B5:B9) -> 6010174.4 | C10: =SUM(C5:C9) -> 1773239.4 | E10: =SUM(E5:E9) -> 602

Sheet Sales-Profit by Category
A1: Sales & Profit by Category and Sub-Category (Completed Orders Only)
A4: Category | B4: Sub-Category | C4: Completed Sales (₹) | D4: Completed Profit (₹)
A5: Technology | B5: Copiers | C5: =SUMIFS(CleanRef!$T$2:$T$913,CleanRef!$J$2:$J$913,"Technology",CleanRef!$K$2:$K$913,"Copiers",CleanRef!$AH$2:$AH$913,"Yes") -> 670173.31 | D5: =SUMIFS(CleanRef!$U$2:$U$913,CleanRef!$J$2:$J$913,"Technology",CleanRef!$K$2:$K$913,"Copiers",CleanRef!$AH$2:$AH$913,"Yes") -> 194107.97
A6: Technology | B6: Phones | C6: =SUMIFS(CleanRef!$T$2:$T$913,CleanRef!$J$2:$J$913,"Technology",CleanRef!$K$2:$K$913,"Phones",CleanRef!$AH$2:$AH$913,"Yes") -> 585862.47 | D6: =SUMIFS(CleanRef!$U$2:$U$913,CleanRef!$J$2:$J$913,"Technology",CleanRef!$K$2:$K$913,"Phones",CleanRef!$AH$2:$AH$913,"Yes") -> 170370.8
A7: Furniture | B7: Chairs | C7: =SUMIFS(CleanRef!$T$2:$T$913,CleanRef!$J$2:$J$913,"Furniture",CleanRef!$K$2:$K$913,"Chairs",CleanRef!$AH$2:$AH$913,"Yes") -> 583968.65 | D7: =SUMIFS(CleanRef!$U$2:$U$913,CleanRef!$J$2:$J$913,"Furniture",CleanRef!$K$2:$K$913,"Chairs",CleanRef!$AH$2:$AH$913,"Yes") -> 175651.42
A8: Office Supplies | B8: Storage | C8: =SUMIFS(CleanRef!$T$2:$T$913,CleanRef!$J$2:$J$913,"Office Supplies",CleanRef!$K$2:$K$913,"Storage",CleanRef!$AH$2:$AH$913,"Yes") -> 557307.69 | D8: =SUMIFS(CleanRef!$U$2:$U$913,CleanRef!$J$2:$J$913,"Office Supplies",CleanRef!$K$2:$K$913,"Storage",CleanRef!$AH$2:$AH$913,"Yes") -> 150002.36
A9: Technology | B9: Accessories | C9: =SUMIFS(CleanRef!$T$2:$T$913,CleanRef!$J$2:$J$913,"Technology",CleanRef!$K$2:$K$913,"Accessories",CleanRef!$AH$2:$AH$913,"Yes") -> 530334.76 | D9: =SUMIFS(CleanRef!$U$2:$U$913,CleanRef!$J$2:$J$913,"Technology",CleanRef!$K$2:$K$913,"Accessories",CleanRef!$AH$2:$AH$913,"Yes") -> 158243.77
A10: Furniture | B10: Furnishings | C10: =SUMIFS(CleanRef!$T$2:$T$913,CleanRef!$J$2:$J$913,"Furniture",CleanRef!$K$2:$K$913,"Furnishings",CleanRef!$AH$2:$AH$913,"Yes") -> 503021.35 | D10: =SUMIFS(CleanRef!$U$2:$U$913,CleanRef!$J$2:$J$913,"Furniture",CleanRef!$K$2:$K$913,"Furnishings",CleanRef!$AH$2:$AH$913,"Yes") -> 146832.71
A11: Office Supplies | B11: Paper | C11: =SUMIFS(CleanRef!$T$2:$T$913,CleanRef!$J$2:$J$913,"Office Supplies",CleanRef!$K$2:$K$913,"Paper",CleanRef!$AH$2:$AH$913,"Yes") -> 447884.39 | D11: =SUMIFS(CleanRef!$U$2:$U$913,CleanRef!$J$2:$J$913,"Office Supplies",CleanRef!$K$2:$K$913,"Paper",CleanRef!$AH$2:$AH$913,"Yes") -> 123501.05
A12: Technology | B12: Machines | C12: =SUMIFS(CleanRef!$T$2:$T$913,CleanRef!$J$2:$J$913,"Technology",CleanRef!$K$2:$K$913,"Machines",CleanRef!$AH$2:$AH$913,"Yes") -> 429529.93 | D12: =SUMIFS(CleanRef!$U$2:$U$913,CleanRef!$J$2:$J$913,"Technology",CleanRef!$K$2:$K$913,"Machines",CleanRef!$AH$2:$AH$913,"Yes") -> 148398.06
A13: Furniture | B13: Bookcases | C13: =SUMIFS(CleanRef!$T$2:$T$913,CleanRef!$J$2:$J$913,"Furniture",CleanRef!$K$2:$K$913,"Bookcases",CleanRef!$AH$2:$AH$913,"Yes") -> 426946.02 | D13: =SUMIFS(CleanRef!$U$2:$U$913,CleanRef!$J$2:$J$913,"Furniture",CleanRef!$K$2:$K$913,"Bookcases",CleanRef!$AH$2:$AH$913,"Yes") -> 121943.99
A14: Furniture | B14: Tables | C14: =SUMIFS(CleanRef!$T$2:$T$913,CleanRef!$J$2:$J$913,"Furniture",CleanRef!$K$2:$K$913,"Tables",CleanRef!$AH$2:$AH$913,"Yes") -> 420185.33 | D14: =SUMIFS(CleanRef!$U$2:$U$913,CleanRef!$J$2:$J$913,"Furniture",CleanRef!$K$2:$K$913,"Tables",CleanRef!$AH$2:$AH$913,"Yes") -> 127253.69
A15: Office Supplies | B15: Binders | C15: =SUMIFS(CleanRef!$T$2:$T$913,CleanRef!$J$2:$J$913,"Office Supplies",CleanRef!$K$2:$K$913,"Binders",CleanRef!$AH$2:$AH$913,"Yes") -> 342853.56 | D15: =SUMIFS(CleanRef!$U$2:$U$913,CleanRef!$J$2:$J$913,"Office Supplies",CleanRef!$K$2:$K$913,"Binders",CleanRef!$AH$2:$AH$913,"Yes") -> 109222.19
A16: Office Supplies | B16: Art | C16: =SUMIFS(CleanRef!$T$2:$T$913,CleanRef!$J$2:$J$913,"Office Supplies",CleanRef!$K$2:$K$913,"Art",CleanRef!$AH$2:$AH$913,"Yes") -> 302936.38 | D16: =SUMIFS(CleanRef!$U$2:$U$913,CleanRef!$J$2:$J$913,"Office Supplies",CleanRef!$K$2:$K$913,"Art",CleanRef!$AH$2:$AH$913,"Yes") -> 82544.723
A17: Office Supplies | B17: Labels | C17: =SUMIFS(CleanRef!$T$2:$T$913,CleanRef!$J$2:$J$913,"Office Supplies",CleanRef!$K$2:$K$913,"Labels",CleanRef!$AH$2:$AH$913,"Yes") -> 209170.53 | D17: =SUMIFS(CleanRef!$U$2:$U$913,CleanRef!$J$2:$J$913,"Office Supplies",CleanRef!$K$2:$K$913,"Labels",CleanRef!$AH$2:$AH$913,"Yes") -> 65166.618
B18: TOTAL | C18: =SUM(C5:C17) -> 6010174.4 | D18: =SUM(D5:D17) -> 1773239.4

Sheet Order Count by Ship Mode
A1: Order Count by Ship Mode (All Orders)
A3: Ship Mode | B3: Order Count | C3: % of Total Orders
A4: Standard Class | B4: =COUNTIF(CleanRef!$M$2:$M$913,"Standard Class") -> 242 | C4: =B4/COUNTA(CleanRef!$A$2:$A$913) -> 0.26535088
A5: First Class | B5: =COUNTIF(CleanRef!$M$2:$M$913,"First Class") -> 223 | C5: =B5/COUNTA(CleanRef!$A$2:$A$913) -> 0.24451754
A6: Second Class | B6: =COUNTIF(CleanRef!$M$2:$M$913,"Second Class") -> 222 | C6: =B6/COUNTA(CleanRef!$A$2:$A$913) -> 0.24342105
A7: Same Day | B7: =COUNTIF(CleanRef!$M$2:$M$913,"Same Day") -> 204 | C7: =B7/COUNTA(CleanRef!$A$2:$A$913) -> 0.22368421
A8: Unknown | B8: =COUNTIF(CleanRef!$M$2:$M$913,"Unknown") -> 21 | C8: =B8/COUNTA(CleanRef!$A$2:$A$913) -> 0.023026316
A9: TOTAL | B9: =SUM(B4:B8) -> 912

Sheet Profit Margin by Segment
A1: Profit Margin by Customer Segment (Completed Orders Only)
A4: Segment | B4: Completed Sales (₹) | C4: Completed Profit (₹) | D4: Profit Margin
A5: Home Office | B5: =SUMIFS(CleanRef!$T$2:$T$913,CleanRef!$F$2:$F$913,"Home Office",CleanRef!$AH$2:$AH$913,"Yes") -> 1564214.5 | C5: =SUMIFS(CleanRef!$U$2:$U$913,CleanRef!$F$2:$F$913,"Home Office",CleanRef!$AH$2:$AH$913,"Yes") -> 474152.64 | D5: =IF(B5=0,0,C5/B5) -> 0.30312507
A6: Consumer | B6: =SUMIFS(CleanRef!$T$2:$T$913,CleanRef!$F$2:$F$913,"Consumer",CleanRef!$AH$2:$AH$913,"Yes") -> 1472995.9 | C6: =SUMIFS(CleanRef!$U$2:$U$913,CleanRef!$F$2:$F$913,"Consumer",CleanRef!$AH$2:$AH$913,"Yes") -> 438320.58 | D6: =IF(B6=0,0,C6/B6) -> 0.29757081
A7: Corporate | B7: =SUMIFS(CleanRef!$T$2:$T$913,CleanRef!$F$2:$F$913,"Corporate",CleanRef!$AH$2:$AH$913,"Yes") -> 1312159.6 | C7: =SUMIFS(CleanRef!$U$2:$U$913,CleanRef!$F$2:$F$913,"Corporate",CleanRef!$AH$2:$AH$913,"Yes") -> 386126.62 | D7: =IF(B7=0,0,C7/B7) -> 0.29426802
A8: Small Business | B8: =SUMIFS(CleanRef!$T$2:$T$913,CleanRef!$F$2:$F$913,"Small Business",CleanRef!$AH$2:$AH$913,"Yes") -> 1660804.3 | C8: =SUMIFS(CleanRef!$U$2:$U$913,CleanRef!$F$2:$F$913,"Small Business",CleanRef!$AH$2:$AH$913,"Yes") -> 474639.52 | D8: =IF(B8=0,0,C8/B8) -> 0.28578894

Sheet Refunded-Cancelled-Failed
A1: Refunded, Cancelled & Failed Orders by Region
A3: Region | B3: Refunded (payment_status) | C3: Cancelled (order_status) | D3: Failed Payment (payment_status)
A4: East | B4: =COUNTIFS(CleanRef!$G$2:$G$913,"East",CleanRef!$Z$2:$Z$913,"Refunded") -> 14 | C4: =COUNTIFS(CleanRef!$G$2:$G$913,"East",CleanRef!$AA$2:$AA$913,"Cancelled") -> 30 | D4: =COUNTIFS(CleanRef!$G$2:$G$913,"East",CleanRef!$Z$2:$Z$913,"Failed") -> 13
A5: North | B5: =COUNTIFS(CleanRef!$G$2:$G$913,"North",CleanRef!$Z$2:$Z$913,"Refunded") -> 20 | C5: =COUNTIFS(CleanRef!$G$2:$G$913,"North",CleanRef!$AA$2:$AA$913,"Cancelled") -> 48 | D5: =COUNTIFS(CleanRef!$G$2:$G$913,"North",CleanRef!$Z$2:$Z$913,"Failed") -> 20
A6: South | B6: =COUNTIFS(CleanRef!$G$2:$G$913,"South",CleanRef!$Z$2:$Z$913,"Refunded") -> 20 | C6: =COUNTIFS(CleanRef!$G$2:$G$913,"South",CleanRef!$AA$2:$AA$913,"Cancelled") -> 35 | D6: =COUNTIFS(CleanRef!$G$2:$G$913,"South",CleanRef!$Z$2:$Z$913,"Failed") -> 20
A7: West | B7: =COUNTIFS(CleanRef!$G$2:$G$913,"West",CleanRef!$Z$2:$Z$913,"Refunded") -> 14 | C7: =COUNTIFS(CleanRef!$G$2:$G$913,"West",CleanRef!$AA$2:$AA$913,"Cancelled") -> 30 | D7: =COUNTIFS(CleanRef!$G$2:$G$913,"West",CleanRef!$Z$2:$Z$913,"Failed") -> 14
A8: Unknown | B8: =COUNTIFS(CleanRef!$G$2:$G$913,"Unknown",CleanRef!$Z$2:$Z$913,"Refunded") -> 3 | C8: =COUNTIFS(CleanRef!$G$2:$G$913,"Unknown",CleanRef!$AA$2:$AA$913,"Cancelled") -> 2 | D8: =COUNTIFS(CleanRef!$G$2:$G$913,"Unknown",CleanRef!$Z$2:$Z$913,"Failed") -> 2
A9: TOTAL | B9: =SUM(B4:B8) -> 71 | C9: =SUM(C4:C8) -> 145 | D9: =SUM(D4:D8) -> 69

Sheet Monthly Sales Trend
A1: Monthly Sales Trend (Completed Orders Only)
A4: Year-Month | B4: Completed Sales (₹) | C4: Completed Profit (₹) | D4: Completed Orders
A5: January 2024 | B5: =SUMIFS(CleanRef!$T$2:$T$913,CleanRef!$Y$2:$Y$913,2024,CleanRef!$X$2:$X$913,"January",CleanRef!$AH$2:$AH$913,"Yes") -> 257280.76 | C5: =SUMIFS(CleanRef!$U$2:$U$913,CleanRef!$Y$2:$Y$913,2024,CleanRef!$X$2:$X$913,"January",CleanRef!$AH$2:$AH$913,"Yes") -> 93253.285 | D5: =COUNTIFS(CleanRef!$Y$2:$Y$913,2024,CleanRef!$X$2:$X$913,"January",CleanRef!$AH$2:$AH$913,"Yes") -> 28
A6: February 2024 | B6: =SUMIFS(CleanRef!$T$2:$T$913,CleanRef!$Y$2:$Y$913,2024,CleanRef!$X$2:$X$913,"February",CleanRef!$AH$2:$AH$913,"Yes") -> 272999.97 | C6: =SUMIFS(CleanRef!$U$2:$U$913,CleanRef!$Y$2:$Y$913,2024,CleanRef!$X$2:$X$913,"February",CleanRef!$AH$2:$AH$913,"Yes") -> 85401.396 | D6: =COUNTIFS(CleanRef!$Y$2:$Y$913,2024,CleanRef!$X$2:$X$913,"February",CleanRef!$AH$2:$AH$913,"Yes") -> 28
A7: March 2024 | B7: =SUMIFS(CleanRef!$T$2:$T$913,CleanRef!$Y$2:$Y$913,2024,CleanRef!$X$2:$X$913,"March",CleanRef!$AH$2:$AH$913,"Yes") -> 248995 | C7: =SUMIFS(CleanRef!$U$2:$U$913,CleanRef!$Y$2:$Y$913,2024,CleanRef!$X$2:$X$913,"March",CleanRef!$AH$2:$AH$913,"Yes") -> 76783.94 | D7: =COUNTIFS(CleanRef!$Y$2:$Y$913,2024,CleanRef!$X$2:$X$913,"March",CleanRef!$AH$2:$AH$913,"Yes") -> 27
A8: April 2024 | B8: =SUMIFS(CleanRef!$T$2:$T$913,CleanRef!$Y$2:$Y$913,2024,CleanRef!$X$2:$X$913,"April",CleanRef!$AH$2:$AH$913,"Yes") -> 241541.51 | C8: =SUMIFS(CleanRef!$U$2:$U$913,CleanRef!$Y$2:$Y$913,2024,CleanRef!$X$2:$X$913,"April",CleanRef!$AH$2:$AH$913,"Yes") -> 67927.845 | D8: =COUNTIFS(CleanRef!$Y$2:$Y$913,2024,CleanRef!$X$2:$X$913,"April",CleanRef!$AH$2:$AH$913,"Yes") -> 21
A9: May 2024 | B9: =SUMIFS(CleanRef!$T$2:$T$913,CleanRef!$Y$2:$Y$913,2024,CleanRef!$X$2:$X$913,"May",CleanRef!$AH$2:$AH$913,"Yes") -> 359038.68 | C9: =SUMIFS(CleanRef!$U$2:$U$913,CleanRef!$Y$2:$Y$913,2024,CleanRef!$X$2:$X$913,"May",CleanRef!$AH$2:$AH$913,"Yes") -> 91003.629 | D9: =COUNTIFS(CleanRef!$Y$2:$Y$913,2024,CleanRef!$X$2:$X$913,"May",CleanRef!$AH$2:$AH$913,"Yes") -> 34
A10: June 2024 | B10: =SUMIFS(CleanRef!$T$2:$T$913,CleanRef!$Y$2:$Y$913,2024,CleanRef!$X$2:$X$913,"June",CleanRef!$AH$2:$AH$913,"Yes") -> 395531.12 | C10: =SUMIFS(CleanRef!$U$2:$U$913,CleanRef!$Y$2:$Y$913,2024,CleanRef!$X$2:$X$913,"June",CleanRef!$AH$2:$AH$913,"Yes") -> 116614.76 | D10: =COUNTIFS(CleanRef!$Y$2:$Y$913,2024,CleanRef!$X$2:$X$913,"June",CleanRef!$AH$2:$AH$913,"Yes") -> 33
A11: July 2024 | B11: =SUMIFS(CleanRef!$T$2:$T$913,CleanRef!$Y$2:$Y$913,2024,CleanRef!$X$2:$X$913,"July",CleanRef!$AH$2:$AH$913,"Yes") -> 235720.3 | C11: =SUMIFS(CleanRef!$U$2:$U$913,CleanRef!$Y$2:$Y$913,2024,CleanRef!$X$2:$X$913,"July",CleanRef!$AH$2:$AH$913,"Yes") -> 62651.655 | D11: =COUNTIFS(CleanRef!$Y$2:$Y$913,2024,CleanRef!$X$2:$X$913,"July",CleanRef!$AH$2:$AH$913,"Yes") -> 27
A12: August 2024 | B12: =SUMIFS(CleanRef!$T$2:$T$913,CleanRef!$Y$2:$Y$913,2024,CleanRef!$X$2:$X$913,"August",CleanRef!$AH$2:$AH$913,"Yes") -> 241428.67 | C12: =SUMIFS(CleanRef!$U$2:$U$913,CleanRef!$Y$2:$Y$913,2024,CleanRef!$X$2:$X$913,"August",CleanRef!$AH$2:$AH$913,"Yes") -> 74723.395 | D12: =COUNTIFS(CleanRef!$Y$2:$Y$913,2024,CleanRef!$X$2:$X$913,"August",CleanRef!$AH$2:$AH$913,"Yes") -> 30
A13: September 2024 | B13: =SUMIFS(CleanRef!$T$2:$T$913,CleanRef!$Y$2:$Y$913,2024,CleanRef!$X$2:$X$913,"September",CleanRef!$AH$2:$AH$913,"Yes") -> 226234.27 | C13: =SUMIFS(CleanRef!$U$2:$U$913,CleanRef!$Y$2:$Y$913,2024,CleanRef!$X$2:$X$913,"September",CleanRef!$AH$2:$AH$913,"Yes") -> 57228.045 | D13: =COUNTIFS(CleanRef!$Y$2:$Y$913,2024,CleanRef!$X$2:$X$913,"September",CleanRef!$AH$2:$AH$913,"Yes") -> 23
A14: October 2024 | B14: =SUMIFS(CleanRef!$T$2:$T$913,CleanRef!$Y$2:$Y$913,2024,CleanRef!$X$2:$X$913,"October",CleanRef!$AH$2:$AH$913,"Yes") -> 351284.32 | C14: =SUMIFS(CleanRef!$U$2:$U$913,CleanRef!$Y$2:$Y$913,2024,CleanRef!$X$2:$X$913,"October",CleanRef!$AH$2:$AH$913,"Yes") -> 100336.11 | D14: =COUNTIFS(CleanRef!$Y$2:$Y$913,2024,CleanRef!$X$2:$X$913,"October",CleanRef!$AH$2:$AH$913,"Yes") -> 30
A15: November 2024 | B15: =SUMIFS(CleanRef!$T$2:$T$913,CleanRef!$Y$2:$Y$913,2024,CleanRef!$X$2:$X$913,"November",CleanRef!$AH$2:$AH$913,"Yes") -> 260061.65 | C15: =SUMIFS(CleanRef!$U$2:$U$913,CleanRef!$Y$2:$Y$913,2024,CleanRef!$X$2:$X$913,"November",CleanRef!$AH$2:$AH$913,"Yes") -> 91770.353 | D15: =COUNTIFS(CleanRef!$Y$2:$Y$913,2024,CleanRef!$X$2:$X$913,"November",CleanRef!$AH$2:$AH$913,"Yes") -> 23
A16: December 2024 | B16: =SUMIFS(CleanRef!$T$2:$T$913,CleanRef!$Y$2:$Y$913,2024,CleanRef!$X$2:$X$913,"December",CleanRef!$AH$2:$AH$913,"Yes") -> 201157.16 | C16: =SUMIFS(CleanRef!$U$2:$U$913,CleanRef!$Y$2:$Y$913,2024,CleanRef!$X$2:$X$913,"December",CleanRef!$AH$2:$AH$913,"Yes") -> 56327.187 | D16: =COUNTIFS(CleanRef!$Y$2:$Y$913,2024,CleanRef!$X$2:$X$913,"December",CleanRef!$AH$2:$AH$913,"Yes") -> 24
A17: January 2025 | B17: =SUMIFS(CleanRef!$T$2:$T$913,CleanRef!$Y$2:$Y$913,2025,CleanRef!$X$2:$X$913,"January",CleanRef!$AH$2:$AH$913,"Yes") -> 272866.44 | C17: =SUMIFS(CleanRef!$U$2:$U$913,CleanRef!$Y$2:$Y$913,2025,CleanRef!$X$2:$X$913,"January",CleanRef!$AH$2:$AH$913,"Yes") -> 76028.785 | D17: =COUNTIFS(CleanRef!$Y$2:$Y$913,2025,CleanRef!$X$2:$X$913,"January",CleanRef!$AH$2:$AH$913,"Yes") -> 27
A18: February 2025 | B18: =SUMIFS(CleanRef!$T$2:$T$913,CleanRef!$Y$2:$Y$913,2025,CleanRef!$X$2:$X$913,"February",CleanRef!$AH$2:$AH$913,"Yes") -> 394995.72 | C18: =SUMIFS(CleanRef!$U$2:$U$913,CleanRef!$Y$2:$Y$913,2025,CleanRef!$X$2:$X$913,"February",CleanRef!$AH$2:$AH$913,"Yes") -> 117043.43 | D18: =COUNTIFS(CleanRef!$Y$2:$Y$913,2025,CleanRef!$X$2:$X$913,"February",CleanRef!$AH$2:$AH$913,"Yes") -> 39
A19: March 2025 | B19: =SUMIFS(CleanRef!$T$2:$T$913,CleanRef!$Y$2:$Y$913,2025,CleanRef!$X$2:$X$913,"March",CleanRef!$AH$2:$AH$913,"Yes") -> 322614.29 | C19: =SUMIFS(CleanRef!$U$2:$U$913,CleanRef!$Y$2:$Y$913,2025,CleanRef!$X$2:$X$913,"March",CleanRef!$AH$2:$AH$913,"Yes") -> 92228.466 | D19: =COUNTIFS(CleanRef!$Y$2:$Y$913,2025,CleanRef!$X$2:$X$913,"March",CleanRef!$AH$2:$AH$913,"Yes") -> 27
A20: April 2025 | B20: =SUMIFS(CleanRef!$T$2:$T$913,CleanRef!$Y$2:$Y$913,2025,CleanRef!$X$2:$X$913,"April",CleanRef!$AH$2:$AH$913,"Yes") -> 293107.4 | C20: =SUMIFS(CleanRef!$U$2:$U$913,CleanRef!$Y$2:$Y$913,2025,CleanRef!$X$2:$X$913,"April",CleanRef!$AH$2:$AH$913,"Yes") -> 80559.25 | D20: =COUNTIFS(CleanRef!$Y$2:$Y$913,2025,CleanRef!$X$2:$X$913,"April",CleanRef!$AH$2:$AH$913,"Yes") -> 35
A21: May 2025 | B21: =SUMIFS(CleanRef!$T$2:$T$913,CleanRef!$Y$2:$Y$913,2025,CleanRef!$X$2:$X$913,"May",CleanRef!$AH$2:$AH$913,"Yes") -> 246177.85 | C21: =SUMIFS(CleanRef!$U$2:$U$913,CleanRef!$Y$2:$Y$913,2025,CleanRef!$X$2:$X$913,"May",CleanRef!$AH$2:$AH$913,"Yes") -> 76545.446 | D21: =COUNTIFS(CleanRef!$Y$2:$Y$913,2025,CleanRef!$X$2:$X$913,"May",CleanRef!$AH$2:$AH$913,"Yes") -> 24
A22: June 2025 | B22: =SUMIFS(CleanRef!$T$2:$T$913,CleanRef!$Y$2:$Y$913,2025,CleanRef!$X$2:$X$913,"June",CleanRef!$AH$2:$AH$913,"Yes") -> 228915.65 | C22: =SUMIFS(CleanRef!$U$2:$U$913,CleanRef!$Y$2:$Y$913,2025,CleanRef!$X$2:$X$913,"June",CleanRef!$AH$2:$AH$913,"Yes") -> 67418.02 | D22: =COUNTIFS(CleanRef!$Y$2:$Y$913,2025,CleanRef!$X$2:$X$913,"June",CleanRef!$AH$2:$AH$913,"Yes") -> 27
A23: July 2025 | B23: =SUMIFS(CleanRef!$T$2:$T$913,CleanRef!$Y$2:$Y$913,2025,CleanRef!$X$2:$X$913,"July",CleanRef!$AH$2:$AH$913,"Yes") -> 258764.04 | C23: =SUMIFS(CleanRef!$U$2:$U$913,CleanRef!$Y$2:$Y$913,2025,CleanRef!$X$2:$X$913,"July",CleanRef!$AH$2:$AH$913,"Yes") -> 74288.206 | D23: =COUNTIFS(CleanRef!$Y$2:$Y$913,2025,CleanRef!$X$2:$X$913,"July",CleanRef!$AH$2:$AH$913,"Yes") -> 23
A24: August 2025 | B24: =SUMIFS(CleanRef!$T$2:$T$913,CleanRef!$Y$2:$Y$913,2025,CleanRef!$X$2:$X$913,"August",CleanRef!$AH$2:$AH$913,"Yes") -> 262335.28 | C24: =SUMIFS(CleanRef!$U$2:$U$913,CleanRef!$Y$2:$Y$913,2025,CleanRef!$X$2:$X$913,"August",CleanRef!$AH$2:$AH$913,"Yes") -> 82704.965 | D24: =COUNTIFS(CleanRef!$Y$2:$Y$913,2025,CleanRef!$X$2:$X$913,"August",CleanRef!$AH$2:$AH$913,"Yes") -> 33
A25: September 2025 | B25: =SUMIFS(CleanRef!$T$2:$T$913,CleanRef!$Y$2:$Y$913,2025,CleanRef!$X$2:$X$913,"September",CleanRef!$AH$2:$AH$913,"Yes") -> 317689.5 | C25: =SUMIFS(CleanRef!$U$2:$U$913,CleanRef!$Y$2:$Y$913,2025,CleanRef!$X$2:$X$913,"September",CleanRef!$AH$2:$AH$913,"Yes") -> 95438.908 | D25: =COUNTIFS(CleanRef!$Y$2:$Y$913,2025,CleanRef!$X$2:$X$913,"September",CleanRef!$AH$2:$AH$913,"Yes") -> 29
A26: October 2025 | B26: =SUMIFS(CleanRef!$T$2:$T$913,CleanRef!$Y$2:$Y$913,2025,CleanRef!$X$2:$X$913,"October",CleanRef!$AH$2:$AH$913,"Yes") -> 121434.8 | C26: =SUMIFS(CleanRef!$U$2:$U$913,CleanRef!$Y$2:$Y$913,2025,CleanRef!$X$2:$X$913,"October",CleanRef!$AH$2:$AH$913,"Yes") -> 36962.274 | D26: =COUNTIFS(CleanRef!$Y$2:$Y$913,2025,CleanRef!$X$2:$X$913,"October",CleanRef!$AH$2:$AH$913,"Yes") -> 10
A27: November 2025 | B27: =SUMIFS(CleanRef!$T$2:$T$913,CleanRef!$Y$2:$Y$913,2025,CleanRef!$X$2:$X$913,"November",CleanRef!$AH$2:$AH$913,"Yes") -> 0 | C27: =SUMIFS(CleanRef!$U$2:$U$913,CleanRef!$Y$2:$Y$913,2025,CleanRef!$X$2:$X$913,"November",CleanRef!$AH$2:$AH$913,"Yes") -> 0 | D27: =COUNTIFS(CleanRef!$Y$2:$Y$913,2025,CleanRef!$X$2:$X$913,"November",CleanRef!$AH$2:$AH$913,"Yes") -> 0
A28: December 2025 | B28: =SUMIFS(CleanRef!$T$2:$T$913,CleanRef!$Y$2:$Y$913,2025,CleanRef!$X$2:$X$913,"December",CleanRef!$AH$2:$AH$913,"Yes") -> 0 | C28: =SUMIFS(CleanRef!$U$2:$U$913,CleanRef!$Y$2:$Y$913,2025,CleanRef!$X$2:$X$913,"December",CleanRef!$AH$2:$AH$913,"Yes") -> 0 | D28: =COUNTIFS(CleanRef!$Y$2:$Y$913,2025,CleanRef!$X$2:$X$913,"December",CleanRef!$AH$2:$AH$913,"Yes") -> 0
A29: TOTAL | B29: =SUM(B5:B28) -> 6010174.4 | C29: =SUM(C5:C28) -> 1773239.4 | D29: =SUM(D5:D28) -> 602

Sheet CleanRef
A1: order_id | B1: order_date | C1: ship_date | D1: customer_id | E1: customer_name | F1: segment | G1: region | H1: state | I1: city | J1: category | K1: sub_category | L1: product_name | M1: ship_mode | N1: quantity | O1: unit_price | P1: discount_parsed | Q1: cleaned_discount | R1: recorded_sales | S1: cost | T1: calculated_sales | U1: calculated_profit | V1: profit_margin | W1: shipping_delay_days | X1: order_month | Y1: order_year | Z1: payment_status | AA1: order_status | AB1: is_region_filled | AC1: is_shipmode_filled | AD1: is_discount_filled | AE1: is_shipping_invalid | AF1: is_discount_invalid | AG1: is_duplicate_conflict | AH1: is_completed_sale | AI1: data_quality_flag | AJ1: raw_order_date | AK1: raw_ship_date | AL1: raw_customer_name | AM1: raw_segment | AN1: raw_region | AO1: raw_state | AP1: raw_city | AQ1: raw_category | AR1: raw_sub_category | AS1: raw_ship_mode | AT1: raw_discount | AU1: raw_payment_status | AV1: raw_order_status
A2: ORD-2024-10001 | B2: 45494 | C2: 45500 | D2: CUST-4655 | E2: Karan Malhotra | F2: Consumer | G2: North | H2: Rajasthan | I2: Jaipur | J2: Office Supplies | K2: Paper | M2: Second Class | N2: 8 | O2: 2976.45 | P2: 0.2 | Q2: 0.2 | R2: 19049.28 | S2: 15841.89 | T2: 19049.28 | U2: 3207.39 | V2: 0.16837329 | W2: 6 | X2: July | Y2: 2024 | Z2: Paid | AA2: Completed | AB2: No | AC2: No | AD2: No | AE2: No | AF2: No | AG2: No | AH2: Yes | AI2: Clean | AJ2: 21 Jul 2024 | AK2: 07/27/2024 | AL2: Karan Malhotra | AM2: Consumer | AN2: North | AO2: Rajasthan | AP2: Jaipur | AQ2: Office Supplies | AR2: Paper | AS2: Second Class | AT2: 0.2 | AU2: Paid | AV2: Completed
A3: ORD-2024-10002 | B3: 45535 | C3: 45540 | D3: CUST-2054 | E3: Mira Das | F3: Small Business | G3: East | H3: Odisha | I3: Bhubaneswar | J3: Furniture | K3: Tables | M3: Same Day | N3: 3 | O3: 2437.5 | P3: 0 | Q3: 0 | R3: 7312.5 | S3: 4904.73 | T3: 7312.5 | U3: 2407.77 | V3: 0.32926769 | W3: 5 | X3: August | Y3: 2024 | Z3: Paid | AA3: Completed | AB3: No | AC3: No | AD3: No | AE3: No | AF3: No | AG3: No | AH3: Yes | AI3: Clean | AJ3: 08/31/2024 | AK3: 05 Sep 2024 | AL3: Mira Das | AM3: Small Business | AN3: East | AO3: Odisha | AP3: Bhubaneswar | AQ3: Furniture | AR3: Tables | AS3: Same Day | AT3: 0 | AU3: Paid | AV3: Completed
A4: ORD-2024-10003 | B4: 45451 | C4: 45458 | D4: CUST-6843 | E4: Isha Nair | F4: Consumer | G4: East | H4: Odisha | I4: Bhubaneswar | J4: Office Supplies | K4: Art | M4: First Class | N4: 4 | O4: 1065.43 | P4: 0.55 | Q4: 0 | R4: 4261.72 | S4: 2465.69 | T4: 4261.72 | U4: 1796.03 | V4: 0.42143313 | W4: 7 | X4: June | Y4: 2024 | Z4: Paid | AA4: Completed | AB4: No | AC4: No | AD4: No | AE4: No | AF4: Yes | AG4: No | AH4: Yes | AI4: Invalid | AJ4: 06/08/2024 | AK4: 15 Jun 2024 | AL4: Isha Nair | AM4: Consumer | AN4: East | AO4: Odisha | AP4: Bhubaneswar | AQ4: Office Supplies | AR4: Art | AS4: First Class | AT4: 0.55 | AU4: Paid | AV4: Completed
A5: ORD-2024-10004 | B5: 45624 | C5: 45625 | D5: CUST-3722 | E5: Arjun Bose | F5: Small Business | G5: South | H5: Telangana | I5: Hyderabad | J5: Furniture | K5: Furnishings | M5: Standard Class | N5: 6 | O5: 1848.43 | P5: 0.25 | Q5: 0.25 | R5: 8317.93 | S5: 6796.77 | T5: 8317.935 | U5: 1521.165 | V5: 0.18287772 | W5: 1 | X5: November | Y5: 2024 | Z5: Paid | AA5: Completed | AB5: No | AC5: No | AD5: No | AE5: No | AF5: No | AG5: No | AH5: Yes | AI5: Clean | AJ5: 28-11-2024 | AK5: 11/29/2024 | AL5: Arjun Bose | AM5: Small Business | AN5: South | AO5: Telangana | AP5: Hyderabad | AQ5: Furniture | AR5: Furnishings | AS5: Standard Class | AT5: 0.25 | AU5: Paid | AV5: Completed
A6: ORD-2025-10005 | B6: 45898 | C6: 45901 | D6: CUST-8130 | E6: Ananya Rao | F6: Small Business | G6: West | H6: Maharashtra | I6: Mumbai | J6: Furniture | K6: Chairs | M6: First Class | N6: 7 | O6: 2973.76 | P6: 0 | Q6: 0 | R6: 20816.32 | S6: 17705.37 | T6: 20816.32 | U6: 3110.95 | V6: 0.14944764 | W6: 3 | X6: August | Y6: 2025 | Z6: Paid | AA6: Cancelled | AB6: No | AC6: No | AD6: No | AE6: No | AF6: No | AG6: No | AH6: No | AI6: Clean | AJ6: 29 Aug 2025 | AK6: 2025-09-01 | AL6: Ananya Rao | AM6: Small Business | AN6: West | AO6: Maharashtra | AP6: Mumbai | AQ6: Furniture | AR6: Chairs | AS6: First Class | AT6: 0 | AU6: Paid | AV6: Cancelled
A7: ORD-2024-10006 | B7: 45436 | C7: 45440 | D7: CUST-6056 | E7: Vikram Iyer | F7: Small Business | G7: West | H7: Madhya Pradesh | I7: Indore | J7: Technology | K7: Accessories | M7: Same Day | N7: 3 | O7: 1053.11 | P7: 0.2 | Q7: 0.2 | R7: 2527.46 | S7: 1533.58 | T7: 2527.464 | U7: 993.884 | V7: 0.39323369 | W7: 4 | X7: May | Y7: 2024 | Z7: Paid | AA7: Completed | AB7: No | AC7: No | AD7: No | AE7: No | AF7: No | AG7: No | AH7: Yes | AI7: Clean | AJ7: 2024-05-24 | AK7: 28-05-2024 | AL7: Vikram Iyer | AM7: Small Business | AN7: West | AO7: Madhya Pradesh | AP7: Indore | AQ7: Technology | AR7: Accessories | AS7: Same Day | AT7: 0.2 | AU7: Paid | AV7: Completed
A8: ORD-2025-10007 | B8: 45757 | C8: 45763 | D8: CUST-3656 | E8: Neha Gupta | F8: Consumer | G8: East | H8: Odisha | I8: Bhubaneswar | J8: Technology | K8: Copiers | M8: Standard Class | N8: 4 | O8: 1719.87 | P8: 0.15 | Q8: 0.15 | R8: 5847.56 | S8: 4727.25 | T8: 5847.558 | U8: 1120.308 | V8: 0.19158562 | W8: 6 | X8: April | Y8: 2025 | Z8: Paid | AA8: Completed | AB8: No | AC8: No | AD8: No | AE8: No | AF8: No | AG8: No | AH8: Yes | AI8: Clean | AJ8: 04/10/2025 | AK8: 04/16/2025 | AL8: Neha Gupta | AM8: Consumer | AN8: East | AO8: Odisha | AP8: Bhubaneswar | AQ8: Technology | AR8: Copiers | AS8: Standard Class | AT8: 0.15 | AU8: Paid | AV8: Completed
A9: ORD-2025-10008 | B9: 45711 | C9: 45714 | D9: CUST-4683 | E9: Isha Nair | F9: Small Business | G9: South | H9: Andhra Pradesh | I9: Vijayawada | J9: Office Supplies | K9: Art | M9: First Class | N9: 1 | O9: 2980.71 | P9: 0 | Q9: 0 | R9: 2980.71 | S9: 2357.22 | T9: 2980.71 | U9: 623.49 | V9: 0.209175 | W9: 3 | X9: February | Y9: 2025 | Z9: Paid | AA9: Completed | AB9: No | AC9: No | AD9: No | AE9: No | AF9: No | AG9: No | AH9: Yes | AI9: Clean | AJ9: 2025-02-23 | AK9: 26-02-2025 | AL9: Isha Nair | AM9: Small Business | AN9: South | AO9: Andhra Pradesh | AP9: Vijayawada | AQ9: Office Supplies | AR9: Art | AS9: First Class | AT9: 0 | AU9: Paid | AV9: Completed
A10: ORD-2024-10009 | B10: 45601 | C10: 45606 | D10: CUST-2598 | E10: Aditi Sen | F10: Corporate | G10: South | H10: Telangana | I10: Hyderabad | J10: Office Supplies | K10: Labels | M10: First Class | N10: 8 | O10: 3134.2 | P10: 0 | Q10: 0 | R10: 25073.6 | S10: 17347.23 | T10: 25073.6 | U10: 7726.37 | V10: 0.30814761 | W10: 5 | X10: November | Y10: 2024 | Z10: Paid | AA10: Completed | AB10: No | AC10: No | AD10: No | AE10: No | AF10: No | AG10: No | AH10: Yes | AI10: Clean | AJ10: 11/05/2024 | AK10: 11/10/2024 | AL10: Aditi Sen | AM10: Corporate | AN10: South | AO10: Telangana | AP10: Hyderabad | AQ10: Office Supplies | AR10: Labels | AS10: First Class | AT10: 0 | AU10: Paid | AV10: Completed
A11: ORD-2025-10010 | B11: 45907 | C11: 45912 | D11: CUST-2483 | E11: Mira Das | F11: Home Office | G11: South | H11: Telangana | I11: Hyderabad | J11: Office Supplies | K11: Paper | M11: Second Class | N11: 9 | O11: 852.04 | P11: 0.2 | Q11: 0.2 | R11: 6134.69 | S11: 3800.19 | T11: 6134.688 | U11: 2334.498 | V11: 0.38054062 | W11: 5 | X11: September | Y11: 2025 | Z11: Paid | AA11: Completed | AB11: No | AC11: No | AD11: No | AE11: No | AF11: No | AG11: No | AH11: Yes | AI11: Clean | AJ11: 07-09-2025 | AK11: 09/12/2025 | AL11: Mira Das | AM11: Home Office | AN11: South | AO11: Telangana | AP11: Hyderabad | AQ11: Office Supplies | AR11: Paper | AS11: Second Class | AT11: 0.2 | AU11: Paid | AV11: Completed
A12: ORD-2025-10011 | B12: 45797 | C12: 45797 | D12: CUST-8092 | E12: Ananya Rao | F12: Corporate | G12: East | H12: West Bengal | I12: Kolkata | J12: Office Supplies | K12: Labels | M12: Second Class | N12: 3 | O12: 3534.83 | P12: 0.05 | Q12: 0.05 | R12: 10074.27 | S12: 6048.27 | T12: 10074.265 | U12: 4025.9955 | V12: 0.39963167 | W12: 0 | X12: May | Y12: 2025 | Z12: Refunded | AA12: Returned | AB12: No | AC12: No | AD12: No | AE12: No | AF12: No | AG12: No | AH12: No | AI12: Clean | AJ12: 20 May 2025 | AK12: 05/20/2025 | AL12: Ananya Rao | AM12: Corporate | AN12: East | AO12: West Bengal | AP12: Kolkata | AQ12: Office Supplies | AR12: Labels | AS12: Second Class | AT12: 0.05 | AU12: Refunded | AV12: Returned
A13: ORD-2024-10012 | B13: 45495 | C13: 45496 | D13: CUST-6528 | E13: Vikram Iyer | F13: Small Business | G13: East | H13: Odisha | I13: Bhubaneswar | J13: Technology | K13: Accessories | M13: Same Day | N13: 6 | O13: 2005.95 | P13: 0.2 | Q13: 0.2 | R13: 9628.56 | S13: 8038.59 | T13: 9628.56 | U13: 1589.97 | V13: 0.16513061 | W13: 1 | X13: July | Y13: 2024 | Z13: Paid | AA13: Completed | AB13: No | AC13: No | AD13: No | AE13: No | AF13: No | AG13: No | AH13: Yes | AI13: Clean | AJ13: 2024-07-22 | AK13: 23-07-2024 | AL13: Vikram Iyer | AM13: Small Business | AN13: East | AO13: Odisha | AP13: Bhubaneswar | AQ13: Technology | AR13: Accessories | AS13: Same Day | AT13: 0.2 | AU13: Paid | AV13: Completed
... A33: ORD-2025-10032 | B33: 45823 | C33: 45827 | D33: CUST-7867 | E33: Karan Malhotra | F33: Small Business | G33: West | H33: Madhya Pradesh | I33: Indore | J33: Office Supplies | K33: Paper | M33: Second Class | N33: 9 | O33: 3092.55 | P33: 0 | Q33: 0 | R33: 27832.95 | S33: 17769.75 | T33: 27832.95 | U33: 10063.2 | V33: 0.36155708 | W33: 4 | X33: June | Y33: 2025 | Z33: Failed | AA33: Returned | AB33: No | AC33: No | AD33: No | AE33: No | AF33: No | AG33: No | AH33: No | AI33: Clean | AJ33: 15-06-2025 | AK33: 19-06-2025 | AL33: Karan Malhotra | AM33: Small Business | AN33: West | AO33: Madhya Pradesh | AP33: Indore | AQ33: Office Supplies | AR33: Paper | AS33: Second Class | AT33: 0 | AU33: Failed | AV33: Returned
A34: ORD-2024-10033 | B34: 45618 | C34: 45622 | D34: CUST-6509 | E34: Aarav Sharma | F34: Corporate | G34: South | H34: Andhra Pradesh | I34: Vijayawada | J34: Technology | K34: Phones | M34: Second Class | N34: 3 | O34: 4001.25 | Q34: 0 | R34: 9002.81 | S34: 7529.92 | T34: 12003.75 | U34: 4473.83 | V34: 0.3727027 | W34: 4 | X34: November | Y34: 2024 | Z34: Paid | AA34: Completed | AB34: No | AC34: No | AD34: Yes | AE34: No | AF34: No | AG34: No | AH34: Yes | AI34: Warning | AJ34: 22-11-2024 | AK34: 2024-11-26 | AL34: Aarav Sharma | AM34: Corporate | AN34: South | AO34: Andhra Pradesh | AP34: Vijayawada | AQ34: Technology | AR34: Phones | AS34: Second Class | AU34: Paid | AV34: Completed
A35: ORD-2024-10034 | B35: 45495 | C35: 45500 | D35: CUST-6660 | E35: Priya Menon | F35: Home Office | G35: West | H35: Goa | I35: Panaji | J35: Furniture | K35: Tables | M35: Same Day | N35: 7 | O35: 492.41 | P35: 0.25 | Q35: 0.25 | R35: 2585.15 | S35: 2070.73 | T35: 2585.1525 | U35: 514.4225 | V35: 0.19899116 | W35: 5 | X35: July | Y35: 2024 | Z35: Paid | AA35: Completed | AB35: No | AC35: No | AD35: No | AE35: No | AF35: No | AG35: No | AH35: Yes | AI35: Clean | AJ35: 07/22/2024 | AK35: 27-07-2024 | AL35: Priya Menon | AM35: Home Office | AN35: West | AO35: Goa | AP35: Panaji | AQ35: Furniture | AR35: Tables | AS35: Same Day | AT35: 0.25 | AU35: Paid | AV35: Completed
A36: ORD-2025-10035 | B36: 45688 | C36: 45693 | D36: CUST-2392 | E36: Priya Menon | F36: Home Office | G36: East | H36: West Bengal | I36: Kolkata | J36: Furniture | K36: Chairs | M36: Unknown | N36: 2 | O36: 4159.69 | P36: 0.2 | Q36: 0.2 | R36: 6655.5 | S36: 4340.21 | T36: 6655.504 | U36: 2315.294 | V36: 0.34787658 | W36: 5 | X36: January | Y36: 2025 | Z36: Paid | AA36: Completed | AB36: No | AC36: Yes | AD36: No | AE36: No | AF36: No | AG36: No | AH36: Yes | AI36: Warning | AJ36: 2025-01-31 | AK36: 2025-02-05 | AL36: Priya Menon | AM36: Home Office | AN36: East | AO36: West Bengal | AP36: Kolkata | AQ36: Furniture | AR36: Chairs | AT36: 0.2 | AU36: Paid | AV36: Completed
A37: ORD-2024-10036 | B37: 45441 | C37: 45441 | D37: CUST-1611 | E37: Sneha Kapoor | F37: Small Business | G37: West | H37: Gujarat | I37: Ahmedabad | J37: Furniture | K37: Bookcases | M37: Second Class | N37: 8 | O37: 2507.12 | P37: 0.05 | Q37: 0.05 | R37: 19054.11 | S37: 15313.83 | T37: 19054.112 | U37: 3740.282 | V37: 0.19629789 | W37: 0 | X37: May | Y37: 2024 | Z37: Pending | AA37: Returned | AB37: No | AC37: No | AD37: No | AE37: No | AF37: No | AG37: No | AH37: No | AI37: Clean | AJ37: 29-05-2024 | AK37: 29 May 2024 | AL37: Sneha Kapoor | AM37: Small Business | AN37: West | AO37: Gujarat | AP37: Ahmedabad | AQ37: Furniture | AR37: Bookcases | AS37: Second Class | AT37: 0.05 | AU37: Pending | AV37: Returned
A38: ORD-2024-10037 | B38: 45590 | C38: 45593 | D38: CUST-8296 | E38: Rohan Mehta | F38: Corporate | G38: West | H38: Maharashtra | I38: Mumbai | J38: Furniture | K38: Bookcases | M38: Second Class | N38: 3 | O38: 3126.47 | P38: 0 | Q38: 0 | R38: 9379.41 | S38: 6670.85 | T38: 9379.41 | U38: 2708.56 | V38: 0.28877723 | W38: 3 | X38: October | Y38: 2024 | Z38: Paid | AA38: Returned | AB38: No | AC38: No | AD38: No | AE38: No | AF38: No | AG38: No | AH38: No | AI38: Clean | AJ38: 2024-10-25 | AK38: 28 Oct 2024 | AL38: Rohan Mehta | AM38: Corporate | AN38: West | AO38: Maharashtra | AP38: Mumbai | AQ38: Furniture | AR38: Bookcases | AS38: Second Class | AT38: 0 | AU38: Paid | AV38: Returned
A39: ORD-2025-10038 | B39: 45867 | C39: 45867 | D39: CUST-4646 | E39: Diya Patel | F39: Consumer | G39: West | H39: Maharashtra | I39: Mumbai | J39: Technology | K39: Copiers | M39: Standard Class | N39: 4 | O39: 1327.54 | P39: 0.2 | Q39: 0.2 | R39: 4248.13 | S39: 3321.09 | T39: 4248.128 | U39: 927.038 | V39: 0.21822271 | W39: 0 | X39: July | Y39: 2025 | Z39: Paid | AA39: Completed | AB39: No | AC39: No | AD39: No | AE39: No | AF39: No | AG39: No | AH39: Yes | AI39: Clean | AJ39: 29-07-2025 | AK39: 29-07-2025 | AL39: Diya Patel | AM39: Consumer | AN39: West | AO39: Maharashtra | AP39: Mumbai | AQ39: Technology | AR39: Copiers | AS39: STANDARD CLASS | AT39: 0.2 | AU39: Paid | AV39: Completed
A40: ORD-2024-10039 | B40: 45460 | C40: 45465 | D40: CUST-8235 | E40: Aarav Sharma | F40: Corporate | G40: West | H40: Gujarat | I40: Ahmedabad | J40: Technology | K40: Phones | M40: First Class | N40: 7 | O40: 2210.68 | P40: 0.1 | Q40: 0.1 | R40: 13927.28 | S40: 10504.87 | T40: 13927.284 | U40: 3422.414 | V40: 0.24573449 | W40: 5 | X40: June | Y40: 2024 | Z40: Paid | AA40: Completed | AB40: No | AC40: No | AD40: No | AE40: No | AF40: No | AG40: No | AH40: Yes | AI40: Clean | AJ40: 2024-06-17 | AK40: 22-06-2024 | AL40: Aarav Sharma | AM40: Corporate | AN40: West | AO40: Gujarat | AP40: Ahmedabad | AQ40: Technology | AR40: Phones | AS40: First Class | AT40: 0.1 | AU40: Paid | AV40: Completed
A41: ORD-2024-10040 | B41: 45637 | C41: 45637 | D41: CUST-5830 | E41: Mira Das | F41: Small Business | G41: West | H41: Madhya Pradesh | I41: Indore | J41: Technology | K41: Copiers | M41: First Class | N41: 4 | O41: 1370.92 | P41: 0.1 | Q41: 0.1 | R41: 4935.31 | S41: 3374.77 | T41: 4935.312 | U41: 1560.542 | V41: 0.31619926 | W41: 0 | X41: December | Y41: 2024 | Z41: Pending | AA41: Returned | AB41: No | AC41: No | AD41: No | AE41: No | AF41: No | AG41: No | AH41: No | AI41: Clean | AJ41: 12/11/2024 | AK41: 2024-12-11 | AL41: Mira Das | AM41: Small Business | AN41: West | AO41: Madhya Pradesh | AP41: Indore | AQ41: Technology | AR41: Copiers | AS41: First Class | AT41: 0.1 | AU41: Pending | AV41: Returned
A42: ORD-2024-10041 | B42: 45575 | C42: 45581 | D42: CUST-7178 | E42: Isha Nair | F42: Home Office | G42: West | H42: Rajasthan | I42: Udaipur | J42: Technology | K42: Copiers | M42: Standard Class | N42: 7 | O42: 2509.27 | P42: 0.2 | Q42: 0.2 | R42: 14051.91 | S42: 11990.37 | T42: 14051.912 | U42: 2061.542 | V42: 0.146709 | W42: 6 | X42: October | Y42: 2024 | Z42: Paid | AA42: Completed | AB42: No | AC42: No | AD42: No | AE42: No | AF42: No | AG42: No | AH42: Yes | AI42: Clean | AJ42: 10-10-2024 | AK42: 16 Oct 2024 | AL42: Isha Nair | AM42: Home Office | AN42: West | AO42: Rajasthan | AP42: Udaipur | AQ42: Technology | AR42: Copiers | AS42: Standard Class | AT42: 0.2 | AU42: Paid | AV42: Completed
A43: ORD-2024-10042 | B43: 45363 | C43: 45368 | D43: CUST-3829 | E43: Aarav Sharma | F43: Small Business | G43: East | H43: Odisha | I43: Bhubaneswar | J43: Furniture | K43: Bookcases | M43: Same Day | N43: 8 | O43: 855.81 | P43: 0 | Q43: 0 | R43: 6846.48 | S43: 4239.89 | T43: 6846.48 | U43: 2606.59 | V43: 0.38071973 | W43: 5 | X43: March | Y43: 2024 | Z43: Pending | AA43: Cancelled | AB43: No | AC43: No | AD43: No | AE43: No | AF43: No | AG43: No | AH43: No | AI43: Clean | AJ43: 03/12/2024 | AK43: 17-03-2024 | AL43: Aarav Sharma | AM43: Small Business | AN43: East | AO43: Odisha | AP43: Bhubaneswar | AQ43: Furniture | AR43: Bookcases | AS43: Same Day | AT43: 0 | AU43: Pending | AV43: Cancelled
A44: ORD-2025-10043 | B44: 45940 | C44: 45945 | D44: CUST-6708 | E44: Arjun Bose | F44: Corporate | G44: East | H44: Jharkhand | I44: Ranchi | J44: Technology | K44: Phones | M44: Standard Class | N44: 8 | O44: 979.87 | P44: 0.05 | Q44: 0.05 | R44: 7447.01 | S44: 4496.22 | T44: 7447.012 | U44: 2950.792 | V44: 0.39623838 | W44: 5 | X44: October | Y44: 2025 | Z44: Paid | AA44: Completed | AB44: No | AC44: No | AD44: No | AE44: No | AF44: No | AG44: No | AH44: Yes | AI44: Clean | AJ44: 2025-10-10 | AK44: 15 Oct 2025 | AL44: Arjun Bose | AM44: Corporate | AN44: East | AO44: Jharkhand | AP44: Ranchi | AQ44: Technology | AR44: Phones | AS44: Standard Class | AT44: 0.05 | AU44: Paid | AV44: Completed
A45: ORD-2024-10044 | B45: 45481 | C45: 45487 | D45: CUST-7119 | E45: Priya Menon | F45: Small Business | G45: East | H45: Odisha | I45: Bhubaneswar | J45: Furniture | K45: Furnishings | M45: Same Day | N45: 3 | O45: 1010.23 | P45: 0 | Q45: 0 | R45: 3030.69 | S45: 1721.08 | T45: 3030.69 | U45: 1309.61 | V45: 0.43211612 | W45: 6 | X45: July | Y45: 2024 | Z45: Paid | AA45: Completed | AB45: No | AC45: No | AD45: No | AE45: No | AF45: No | AG45: No | AH45: Yes | AI45: Clean | AJ45: 07/08/2024 | AK45: 07/14/2024 | AL45: Priya Menon | AM45: Small Business | AN45: East | AO45: Odisha | AP45: Bhubaneswar | AQ45: Furniture | AR45: Furnishings | AS45: Same Day | AT45: 0 | AU45: Paid | AV45: Completed
A46: ORD-2024-10045 | B46: 45465 | C46: 45468 | D46: CUST-3373 | E46: Rohan Mehta | F46: Small Business | G46: North | H46: Haryana | I46: Gurugram | J46: Furniture | K46: Chairs | M46: Standard Class | N46: 9 | O46: 3329.77 | P46: 0.1 | Q46: 0.1 | R46: 26971.14 | S46: 17376.2 | T46: 26971.137 | U46: 9594.937 | V46: 0.35574833 | W46: 3 | X46: June | Y46: 2024 | Z46: Paid | AA46: Completed | AB46: No | AC46: No | AD46: No | AE46: No | AF46: No | AG46: No | AH46: Yes | AI46: Clean | AJ46: 06/22/2024 | AK46: 25-06-2024 | AL46: Rohan Mehta | AM46: Small Business | AN46: North | AO46: Haryana | AP46: Gurugram | AQ46: Furniture | AR46: Chairs | AS46: Standard Class | AT46: 0.1 | AU46: Paid | AV46: Completed
A47: ORD-2024-10046 | B47: 45309 | C47: 45315 | D47: CUST-8896 | E47: Isha Nair | F47: Home Office | G47: East | H47: Bihar | I47: Patna | J47: Office Supplies | K47: Art | M47: Second Class | N47: 8 | O47: 3927.82 | P47: 0.05 | Q47: 0.05 | R47: 29851.43 | S47: 17487.48 | T47: 29851.432 | U47: 12363.952 | V47: 0.41418288 | W47: 6 | X47: January | Y47: 2024 | Z47: Pending | AA47: Returned | AB47: No | AC47: No | AD47: No | AE47: No | AF47: No | AG47: No | AH47: No | AI47: Clean | AJ47: 18 Jan 2024 | AK47: 24-01-2024 | AL47: Isha Nair | AM47: Home Office | AN47: East | AO47: Bihar | AP47: Patna | AQ47: Office Supplies | AR47: Art | AS47: Second Class | AT47: 0.05 | AU47: Pending | AV47: Returned
A48: ORD-2024-10047 | B48: 45492 | C48: 45492 | D48: CUST-8517 | E48: Ananya Rao | F48: Small Business | G48: South | H48: Kerala | I48: Kochi | J48: Furniture | K48: Bookcases | M48: Standard Class | N48: 9 | O48: 2386.79 | P48: 0.25 | Q48: 0.25 | R48: 16110.83 | S48: 10680.03 | T48: 16110.833 | U48: 5430.8025 | V48: 0.33709012 | W48: 0 | X48: July | Y48: 2024 | Z48: Refunded | AA48: Returned | AB48: No | AC48: No | AD48: No | AE48: No | AF48: No | AG48: No | AH48: No | AI48: Clean | AJ48: 19-07-2024 | AK48: 19-07-2024 | AL48: Ananya Rao | AM48: Small Business | AN48: South | AO48: Kerala | AP48: Kochi | AQ48: Furniture | AR48: Bookcases | AS48: Standard Class | AT48: 0.25 | AU48: Refunded | AV48: Returned
... A59: ORD-2024-10058 | B59: 45329 | C59: 45337 | D59: CUST-9941 | E59: Priya Menon | F59: Consumer | G59: West | H59: Goa | I59: Panaji | J59: Furniture | K59: Chairs | M59: Same Day | N59: 5 | O59: 255.87 | P59: 0 | Q59: 0 | R59: 1279.35 | S59: 1091.54 | T59: 1279.35 | U59: 187.81 | V59: 0.14680111 | W59: 8 | X59: February | Y59: 2024 | Z59: Paid | AA59: Completed | AB59: No | AC59: No | AD59: No | AE59: No | AF59: No | AG59: No | AH59: Yes | AI59: Clean | AJ59: 2024-02-07 | AK59: 15 Feb 2024 | AL59: Priya Menon | AM59: Consumer | AN59: West | AO59: Goa | AP59: Panaji | AQ59: Furniture | AR59: Chairs | AS59: Same Day | AT59: 0 | AU59: Paid | AV59: Completed
A60: ORD-2024-10059 | B60: 45536 | C60: 45542 | D60: CUST-3983 | E60: Isha Nair | F60: Home Office | G60: North | H60: Rajasthan | I60: Jaipur | J60: Office Supplies | K60: Storage | M60: Unknown | N60: 9 | O60: 1389.48 | P60: 0.1 | Q60: 0.1 | R60: 11254.79 | S60: 6578.06 | T60: 11254.788 | U60: 4676.728 | V60: 0.41553231 | W60: 6 | X60: September | Y60: 2024 | Z60: Pending | AA60: Returned | AB60: No | AC60: Yes | AD60: No | AE60: No | AF60: No | AG60: No | AH60: No | AI60: Warning | AJ60: 2024-09-01 | AK60: 2024-09-07 | AL60: Isha Nair | AM60: Home Office | AN60: North | AO60: Rajasthan | AP60: Jaipur | AQ60: Office Supplies | AR60: Storage | AT60: 0.1 | AU60: Pending | AV60: Returned
A61: ORD-2024-10060 | B61: 45493 | C61: 45498 | D61: CUST-2418 | E61: Priya Menon | F61: Corporate | G61: East | H61: Assam | I61: Guwahati | J61: Office Supplies | K61: Labels | M61: Same Day | N61: 5 | O61: 4133.85 | P61: 0.2 | Q61: 0.2 | R61: 16535.4 | S61: 12990.21 | T61: 16535.4 | U61: 3545.19 | V61: 0.21440001 | W61: 5 | X61: July | Y61: 2024 | Z61: Paid | AA61: Cancelled | AB61: No | AC61: No | AD61: No | AE61: No | AF61: No | AG61: No | AH61: No | AI61: Clean | AJ61: 20-07-2024 | AK61: 25 Jul 2024 | AL61: Priya Menon | AM61: Corporate | AN61: East | AO61: Assam | AP61: Guwahati | AQ61: Office Supplies | AR61: Labels | AS61: Same Day | AT61: 0.2 | AU61: Paid | AV61: Cancelled
A62: ORD-2024-10061 | B62: 45486 | C62: 45492 | D62: CUST-2892 | E62: Ananya Rao | F62: Corporate | G62: East | H62: Assam | I62: Guwahati | J62: Office Supplies | K62: Labels | M62: Same Day | N62: 3 | O62: 275.76 | P62: 0.2 | Q62: 0.2 | R62: 661.82 | S62: 481.47 | T62: 661.824 | U62: 180.354 | V62: 0.27251052 | W62: 6 | X62: July | Y62: 2024 | Z62: Refunded | AA62: Cancelled | AB62: No | AC62: No | AD62: No | AE62: No | AF62: No | AG62: No | AH62: No | AI62: Clean | AJ62: 07/13/2024 | AK62: 2024-07-19 | AL62: Ananya Rao | AM62: Corporate | AN62: East | AO62: Assam | AP62: Guwahati | AQ62: Office Supplies | AR62: Labels | AS62: Same Day | AT62: 0.2 | AU62: Refunded | AV62: Cancelled
A63: ORD-2024-10062 | B63: 45398 | C63: 45398 | D63: CUST-7008 | E63: Vikram Iyer | F63: Home Office | G63: East | H63: Bihar | I63: Patna | J63: Furniture | K63: Bookcases | M63: Standard Class | N63: 1 | O63: 949.59 | P63: 0 | Q63: 0 | R63: 949.59 | S63: 751.25 | T63: 949.59 | U63: 198.34 | V63: 0.20886909 | W63: 0 | X63: April | Y63: 2024 | Z63: Paid | AA63: Completed | AB63: No | AC63: No | AD63: No | AE63: No | AF63: No | AG63: No | AH63: Yes | AI63: Clean | AJ63: 16 Apr 2024 | AK63: 04/16/2024 | AL63: Vikram Iyer | AM63: Home Office | AN63: East | AO63: Bihar | AP63: Patna | AQ63: Furniture | AR63: Bookcases | AS63: Standard Class | AT63: 0 | AU63: Paid | AV63: Completed
A64: ORD-2024-10063 | B64: 45595 | C64: 45598 | D64: CUST-4900 | E64: Sneha Kapoor | F64: Home Office | G64: North | H64: Rajasthan | I64: Jaipur | J64: Technology | K64: Phones | M64: Standard Class | N64: 9 | O64: 3042.29 | P64: 0.2 | Q64: 0.2 | R64: 21904.49 | S64: 13570.55 | T64: 21904.488 | U64: 8333.938 | V64: 0.38046714 | W64: 3 | X64: October | Y64: 2024 | Z64: Paid | AA64: Completed | AB64: No | AC64: No | AD64: No | AE64: No | AF64: No | AG64: No | AH64: Yes | AI64: Clean | AJ64: 30 Oct 2024 | AK64: 02-11-2024 | AL64: Sneha Kapoor | AM64: Home Office | AN64: North | AO64: Rajasthan | AP64: Jaipur | AQ64: Technology | AR64: Phones | AS64: Standard Class | AT64: 0.2 | AU64: Paid | AV64: Completed
A65: ORD-2024-10064 | B65: 45316 | C65: 45323 | D65: CUST-5382 | E65: Sneha Kapoor | F65: Home Office | G65: North | H65: Haryana | I65: Gurugram | J65: Office Supplies | K65: Binders | M65: Same Day | N65: 2 | O65: 2832.77 | P65: 0.15 | Q65: 0.15 | R65: 4815.71 | S65: 3027.75 | T65: 4815.709 | U65: 1787.959 | V65: 0.37127638 | W65: 7 | X65: January | Y65: 2024 | Z65: Paid | AA65: Completed | AB65: No | AC65: No | AD65: No | AE65: No | AF65: No | AG65: No | AH65: Yes | AI65: Clean | AJ65: 2024-01-25 | AK65: 01-02-2024 | AL65: Sneha Kapoor | AM65: Home Office | AN65: North | AO65: Haryana | AP65: Gurugram | AQ65: Office Supplies | AR65: Binders | AS65: Same Day | AT65: 0.15 | AU65: Paid | AV65: Completed
A66: ORD-2024-10065 | B66: 45649 | C66: 45655 | D66: CUST-2749 | E66: Aarav Sharma | F66: Corporate | G66: East | H66: Jharkhand | I66: Ranchi | J66: Office Supplies | K66: Paper | M66: First Class | N66: 7 | O66: 447.84 | P66: 0 | Q66: 0 | R66: 3134.88 | S66: 2367.63 | T66: 3134.88 | U66: 767.25 | V66: 0.24474621 | W66: 6 | X66: December | Y66: 2024 | Z66: Refunded | AA66: Returned | AB66: No | AC66: No | AD66: No | AE66: No | AF66: No | AG66: No | AH66: No | AI66: Clean | AJ66: 2024-12-23 | AK66: 12/29/2024 | AL66: Aarav Sharma | AM66: Corporate | AN66: East | AO66: Jharkhand | AP66: Ranchi | AQ66: Office Supplies | AR66: Paper | AS66: First Class | AT66: 0 | AU66: Refunded | AV66: Returned
A67: ORD-2024-10066 | B67: 45404 | C67: 45409 | D67: CUST-2463 | E67: Mira Das | F67: Home Office | G67: West | H67: Maharashtra | I67: Mumbai | J67: Office Supplies | K67: Paper | M67: Second Class | N67: 1 | O67: 4280.19 | P67: 0.05 | Q67: 0.05 | R67: 4066.18 | S67: 2628.92 | T67: 4066.1805 | U67: 1437.2605 | V67: 0.35346697 | W67: 5 | X67: April | Y67: 2024 | Z67: Paid | AA67: Completed | AB67: No | AC67: No | AD67: No | AE67: No | AF67: No | AG67: No | AH67: Yes | AI67: Clean | AJ67: 22 Apr 2024 | AK67: 2024-04-27 | AL67: Mira Das | AM67: Home Office | AN67: West | AO67: Maharashtra | AP67: Mumbai | AQ67: Office Supplies | AR67: Paper | AS67: Second Class | AT67: 0.05 | AU67: Paid | AV67: Completed
A68: ORD-2025-10067 | B68: 45897 | C68: 45901 | D68: CUST-1504 | E68: Karan Malhotra | F68: Small Business | G68: South | H68: Tamil Nadu | I68: Chennai | J68: Technology | K68: Accessories | M68: Same Day | N68: 7 | O68: 1057.46 | P68: 0.05 | Q68: 0.05 | R68: 7032.11 | S68: 4610.34 | T68: 7032.109 | U68: 2421.769 | V68: 0.3443873 | W68: 4 | X68: August | Y68: 2025 | Z68: Paid | AA68: Completed | AB68: No | AC68: No | AD68: No | AE68: No | AF68: No | AG68: No | AH68: Yes | AI68: Clean | AJ68: 08/28/2025 | AK68: 01 Sep 2025 | AL68: Karan Malhotra | AM68: Small Business | AN68: South | AO68: Tamil Nadu | AP68: Chennai | AQ68: Technology | AR68: Accessories | AS68: Same Day | AT68: 0.05 | AU68: Paid | AV68: Completed
A69: ORD-2025-10068 | B69: 45691 | C69: 45695 | D69: CUST-8282 | E69: Kabir Singh | F69: Consumer | G69: North | H69: Haryana | I69: Gurugram | J69: Office Supplies | K69: Paper | M69: First Class | N69: 7 | O69: 3609.34 | P69: 0.05 | Q69: 0.05 | R69: 24002.11 | S69: 18707.57 | T69: 24002.111 | U69: 5294.541 | V69: 0.22058647 | W69: 4 | X69: February | Y69: 2025 | Z69: Paid | AA69: Completed | AB69: No | AC69: No | AD69: No | AE69: No | AF69: No | AG69: No | AH69: Yes | AI69: Clean | AJ69: 03 Feb 2025 | AK69: 07-02-2025 | AL69: Kabir Singh | AM69: Consumer | AN69: North | AO69: Haryana | AP69: Gurugram | AQ69: Office Supplies | AR69: Paper | AS69: First Class | AT69: 0.05 | AU69: Paid | AV69: Completed
...
